{"uid":"bc9fa82fde0b0f3f","name":"Get file with incorrect file id","fullName":"tests.files.test_files.TestFiles#test_get_file_with_incorrect_file_id","historyId":"f0e4e32ce5f83acacb9e8ff7318ebd7e","time":{"start":1761074886434,"stop":1761074886434,"duration":0},"status":"broken","statusMessage":"httpx.ConnectError: [Errno 111] Connection refused","statusTrace":"@contextlib.contextmanager\n    def map_httpcore_exceptions() -> typing.Iterator[None]:\n        global HTTPCORE_EXC_MAP\n        if len(HTTPCORE_EXC_MAP) == 0:\n            HTTPCORE_EXC_MAP = _load_httpcore_exceptions()\n        try:\n>           yield\n\n/opt/hostedtoolcache/Python/3.10.18/x64/lib/python3.10/site-packages/httpx/_transports/default.py:101: \n_ _ _ _ _ _ _ _ _ _ _ _ _ _ _ _ _ _ _ _ _ _ _ _ _ _ _ _ _ _ _ _ _ _ _ _ _ _ _ _ \n/opt/hostedtoolcache/Python/3.10.18/x64/lib/python3.10/site-packages/httpx/_transports/default.py:250: in handle_request\n    resp = self._pool.handle_request(req)\n/opt/hostedtoolcache/Python/3.10.18/x64/lib/python3.10/site-packages/httpcore/_sync/connection_pool.py:256: in handle_request\n    raise exc from None\n/opt/hostedtoolcache/Python/3.10.18/x64/lib/python3.10/site-packages/httpcore/_sync/connection_pool.py:236: in handle_request\n    response = connection.handle_request(\n/opt/hostedtoolcache/Python/3.10.18/x64/lib/python3.10/site-packages/httpcore/_sync/connection.py:101: in handle_request\n    raise exc\n/opt/hostedtoolcache/Python/3.10.18/x64/lib/python3.10/site-packages/httpcore/_sync/connection.py:78: in handle_request\n    stream = self._connect(request)\n/opt/hostedtoolcache/Python/3.10.18/x64/lib/python3.10/site-packages/httpcore/_sync/connection.py:124: in _connect\n    stream = self._network_backend.connect_tcp(**kwargs)\n/opt/hostedtoolcache/Python/3.10.18/x64/lib/python3.10/site-packages/httpcore/_backends/sync.py:207: in connect_tcp\n    with map_exceptions(exc_map):\n/opt/hostedtoolcache/Python/3.10.18/x64/lib/python3.10/contextlib.py:153: in __exit__\n    self.gen.throw(typ, value, traceback)\n_ _ _ _ _ _ _ _ _ _ _ _ _ _ _ _ _ _ _ _ _ _ _ _ _ _ _ _ _ _ _ _ _ _ _ _ _ _ _ _ \n\nmap = {<class 'TimeoutError'>: <class 'httpcore.ConnectTimeout'>, <class 'OSError'>: <class 'httpcore.ConnectError'>}\n\n    @contextlib.contextmanager\n    def map_exceptions(map: ExceptionMapping) -> typing.Iterator[None]:\n        try:\n            yield\n        except Exception as exc:  # noqa: PIE786\n            for from_exc, to_exc in map.items():\n                if isinstance(exc, from_exc):\n>                   raise to_exc(exc) from exc\nE                   httpcore.ConnectError: [Errno 111] Connection refused\n\n/opt/hostedtoolcache/Python/3.10.18/x64/lib/python3.10/site-packages/httpcore/_exceptions.py:14: ConnectError\n\nThe above exception was the direct cause of the following exception:\n\npublic_users_client = <clients.users.public_users_client.PublicUsersClient object at 0x7fe144c5d570>\n\n    @pytest.fixture\n    def function_user(public_users_client) -> UserFixture:\n        request = CreateUserRequestSchema()\n>       response = public_users_client.create_user(request)\n\nfixtures/users.py:34: \n_ _ _ _ _ _ _ _ _ _ _ _ _ _ _ _ _ _ _ _ _ _ _ _ _ _ _ _ _ _ _ _ _ _ _ _ _ _ _ _ \nclients/users/public_users_client.py:29: in create_user\n    response = self.create_user_api(request)\nclients/users/public_users_client.py:21: in create_user_api\n    return self.post(url=APIRoutes.USERS, json=request.model_dump(by_alias=True))\nclients/api_client.py:38: in post\n    return self.client.post(url, json=json, data=data, files=files)\n/opt/hostedtoolcache/Python/3.10.18/x64/lib/python3.10/site-packages/httpx/_client.py:1144: in post\n    return self.request(\n/opt/hostedtoolcache/Python/3.10.18/x64/lib/python3.10/site-packages/httpx/_client.py:825: in request\n    return self.send(request, auth=auth, follow_redirects=follow_redirects)\n/opt/hostedtoolcache/Python/3.10.18/x64/lib/python3.10/site-packages/httpx/_client.py:914: in send\n    response = self._send_handling_auth(\n/opt/hostedtoolcache/Python/3.10.18/x64/lib/python3.10/site-packages/httpx/_client.py:942: in _send_handling_auth\n    response = self._send_handling_redirects(\n/opt/hostedtoolcache/Python/3.10.18/x64/lib/python3.10/site-packages/httpx/_client.py:979: in _send_handling_redirects\n    response = self._send_single_request(request)\n/opt/hostedtoolcache/Python/3.10.18/x64/lib/python3.10/site-packages/httpx/_client.py:1014: in _send_single_request\n    response = transport.handle_request(request)\n/opt/hostedtoolcache/Python/3.10.18/x64/lib/python3.10/site-packages/httpx/_transports/default.py:249: in handle_request\n    with map_httpcore_exceptions():\n/opt/hostedtoolcache/Python/3.10.18/x64/lib/python3.10/contextlib.py:153: in __exit__\n    self.gen.throw(typ, value, traceback)\n_ _ _ _ _ _ _ _ _ _ _ _ _ _ _ _ _ _ _ _ _ _ _ _ _ _ _ _ _ _ _ _ _ _ _ _ _ _ _ _ \n\n    @contextlib.contextmanager\n    def map_httpcore_exceptions() -> typing.Iterator[None]:\n        global HTTPCORE_EXC_MAP\n        if len(HTTPCORE_EXC_MAP) == 0:\n            HTTPCORE_EXC_MAP = _load_httpcore_exceptions()\n        try:\n            yield\n        except Exception as exc:\n            mapped_exc = None\n    \n            for from_exc, to_exc in HTTPCORE_EXC_MAP.items():\n                if not isinstance(exc, from_exc):\n                    continue\n                # We want to map to the most specific exception we can find.\n                # Eg if `exc` is an `httpcore.ReadTimeout`, we want to map to\n                # `httpx.ReadTimeout`, not just `httpx.TimeoutException`.\n                if mapped_exc is None or issubclass(to_exc, mapped_exc):\n                    mapped_exc = to_exc\n    \n            if mapped_exc is None:  # pragma: no cover\n                raise\n    \n            message = str(exc)\n>           raise mapped_exc(message) from exc\nE           httpx.ConnectError: [Errno 111] Connection refused\n\n/opt/hostedtoolcache/Python/3.10.18/x64/lib/python3.10/site-packages/httpx/_transports/default.py:118: ConnectError","flaky":false,"newFailed":false,"newBroken":false,"newPassed":false,"retriesCount":0,"retriesStatusChange":false,"beforeStages":[{"name":"_session_faker","time":{"start":1761074885351,"stop":1761074885353,"duration":2},"status":"passed","steps":[],"attachments":[],"parameters":[],"stepsCount":0,"shouldDisplayMessage":false,"attachmentsCount":0,"hasContent":false,"attachmentStep":false},{"name":"save_allure_environment_file","time":{"start":1761074885353,"stop":1761074885353,"duration":0},"status":"passed","steps":[],"attachments":[],"parameters":[],"stepsCount":0,"shouldDisplayMessage":false,"attachmentsCount":0,"hasContent":false,"attachmentStep":false},{"name":"public_users_client","time":{"start":1761074886435,"stop":1761074886456,"duration":21},"status":"passed","steps":[],"attachments":[],"parameters":[],"stepsCount":0,"shouldDisplayMessage":false,"attachmentsCount":0,"hasContent":false,"attachmentStep":false},{"name":"function_user","time":{"start":1761074886456,"stop":1761074886458,"duration":2},"status":"broken","statusMessage":"httpx.ConnectError: [Errno 111] Connection refused\n","statusTrace":"  File \"/opt/hostedtoolcache/Python/3.10.18/x64/lib/python3.10/site-packages/pluggy/_callers.py\", line 38, in run_old_style_hookwrapper\n    res = yield\n  File \"/opt/hostedtoolcache/Python/3.10.18/x64/lib/python3.10/site-packages/pluggy/_callers.py\", line 139, in _multicall\n    teardown.throw(exception)\n  File \"/opt/hostedtoolcache/Python/3.10.18/x64/lib/python3.10/site-packages/pluggy/_callers.py\", line 53, in run_old_style_hookwrapper\n    return result.get_result()\n  File \"/opt/hostedtoolcache/Python/3.10.18/x64/lib/python3.10/site-packages/pluggy/_result.py\", line 103, in get_result\n    raise exc.with_traceback(tb)\n  File \"/opt/hostedtoolcache/Python/3.10.18/x64/lib/python3.10/site-packages/pluggy/_callers.py\", line 38, in run_old_style_hookwrapper\n    res = yield\n  File \"/opt/hostedtoolcache/Python/3.10.18/x64/lib/python3.10/site-packages/pluggy/_callers.py\", line 139, in _multicall\n    teardown.throw(exception)\n  File \"/opt/hostedtoolcache/Python/3.10.18/x64/lib/python3.10/site-packages/_pytest/setuponly.py\", line 36, in pytest_fixture_setup\n    return (yield)\n  File \"/opt/hostedtoolcache/Python/3.10.18/x64/lib/python3.10/site-packages/pluggy/_callers.py\", line 121, in _multicall\n    res = hook_impl.function(*args)\n  File \"/opt/hostedtoolcache/Python/3.10.18/x64/lib/python3.10/site-packages/_pytest/fixtures.py\", line 1196, in pytest_fixture_setup\n    result = call_fixture_func(fixturefunc, request, kwargs)\n  File \"/opt/hostedtoolcache/Python/3.10.18/x64/lib/python3.10/site-packages/_pytest/fixtures.py\", line 930, in call_fixture_func\n    fixture_result = fixturefunc(**kwargs)\n  File \"/home/runner/work/autotest_api/autotest_api/fixtures/users.py\", line 34, in function_user\n    response = public_users_client.create_user(request)\n  File \"/home/runner/work/autotest_api/autotest_api/clients/users/public_users_client.py\", line 29, in create_user\n    response = self.create_user_api(request)\n  File \"/opt/hostedtoolcache/Python/3.10.18/x64/lib/python3.10/site-packages/allure_commons/_allure.py\", line 202, in impl\n    return func(*a, **kw)\n  File \"/home/runner/work/autotest_api/autotest_api/clients/users/public_users_client.py\", line 21, in create_user_api\n    return self.post(url=APIRoutes.USERS, json=request.model_dump(by_alias=True))\n  File \"/opt/hostedtoolcache/Python/3.10.18/x64/lib/python3.10/site-packages/allure_commons/_allure.py\", line 202, in impl\n    return func(*a, **kw)\n  File \"/home/runner/work/autotest_api/autotest_api/clients/api_client.py\", line 38, in post\n    return self.client.post(url, json=json, data=data, files=files)\n  File \"/opt/hostedtoolcache/Python/3.10.18/x64/lib/python3.10/site-packages/httpx/_client.py\", line 1144, in post\n    return self.request(\n  File \"/opt/hostedtoolcache/Python/3.10.18/x64/lib/python3.10/site-packages/httpx/_client.py\", line 825, in request\n    return self.send(request, auth=auth, follow_redirects=follow_redirects)\n  File \"/opt/hostedtoolcache/Python/3.10.18/x64/lib/python3.10/site-packages/httpx/_client.py\", line 914, in send\n    response = self._send_handling_auth(\n  File \"/opt/hostedtoolcache/Python/3.10.18/x64/lib/python3.10/site-packages/httpx/_client.py\", line 942, in _send_handling_auth\n    response = self._send_handling_redirects(\n  File \"/opt/hostedtoolcache/Python/3.10.18/x64/lib/python3.10/site-packages/httpx/_client.py\", line 979, in _send_handling_redirects\n    response = self._send_single_request(request)\n  File \"/opt/hostedtoolcache/Python/3.10.18/x64/lib/python3.10/site-packages/httpx/_client.py\", line 1014, in _send_single_request\n    response = transport.handle_request(request)\n  File \"/opt/hostedtoolcache/Python/3.10.18/x64/lib/python3.10/site-packages/httpx/_transports/default.py\", line 249, in handle_request\n    with map_httpcore_exceptions():\n  File \"/opt/hostedtoolcache/Python/3.10.18/x64/lib/python3.10/contextlib.py\", line 153, in __exit__\n    self.gen.throw(typ, value, traceback)\n  File \"/opt/hostedtoolcache/Python/3.10.18/x64/lib/python3.10/site-packages/httpx/_transports/default.py\", line 118, in map_httpcore_exceptions\n    raise mapped_exc(message) from exc\n","steps":[{"name":"Create user","time":{"start":1761074886457,"stop":1761074886458,"duration":1},"status":"broken","statusMessage":"httpx.ConnectError: [Errno 111] Connection refused\n","statusTrace":"  File \"/opt/hostedtoolcache/Python/3.10.18/x64/lib/python3.10/site-packages/allure_commons/_allure.py\", line 202, in impl\n    return func(*a, **kw)\n  File \"/home/runner/work/autotest_api/autotest_api/clients/users/public_users_client.py\", line 21, in create_user_api\n    return self.post(url=APIRoutes.USERS, json=request.model_dump(by_alias=True))\n  File \"/opt/hostedtoolcache/Python/3.10.18/x64/lib/python3.10/site-packages/allure_commons/_allure.py\", line 202, in impl\n    return func(*a, **kw)\n  File \"/home/runner/work/autotest_api/autotest_api/clients/api_client.py\", line 38, in post\n    return self.client.post(url, json=json, data=data, files=files)\n  File \"/opt/hostedtoolcache/Python/3.10.18/x64/lib/python3.10/site-packages/httpx/_client.py\", line 1144, in post\n    return self.request(\n  File \"/opt/hostedtoolcache/Python/3.10.18/x64/lib/python3.10/site-packages/httpx/_client.py\", line 825, in request\n    return self.send(request, auth=auth, follow_redirects=follow_redirects)\n  File \"/opt/hostedtoolcache/Python/3.10.18/x64/lib/python3.10/site-packages/httpx/_client.py\", line 914, in send\n    response = self._send_handling_auth(\n  File \"/opt/hostedtoolcache/Python/3.10.18/x64/lib/python3.10/site-packages/httpx/_client.py\", line 942, in _send_handling_auth\n    response = self._send_handling_redirects(\n  File \"/opt/hostedtoolcache/Python/3.10.18/x64/lib/python3.10/site-packages/httpx/_client.py\", line 979, in _send_handling_redirects\n    response = self._send_single_request(request)\n  File \"/opt/hostedtoolcache/Python/3.10.18/x64/lib/python3.10/site-packages/httpx/_client.py\", line 1014, in _send_single_request\n    response = transport.handle_request(request)\n  File \"/opt/hostedtoolcache/Python/3.10.18/x64/lib/python3.10/site-packages/httpx/_transports/default.py\", line 249, in handle_request\n    with map_httpcore_exceptions():\n  File \"/opt/hostedtoolcache/Python/3.10.18/x64/lib/python3.10/contextlib.py\", line 153, in __exit__\n    self.gen.throw(typ, value, traceback)\n  File \"/opt/hostedtoolcache/Python/3.10.18/x64/lib/python3.10/site-packages/httpx/_transports/default.py\", line 118, in map_httpcore_exceptions\n    raise mapped_exc(message) from exc\n","steps":[{"name":"Make POST request to '/api/v1/users'","time":{"start":1761074886457,"stop":1761074886458,"duration":1},"status":"broken","statusMessage":"httpx.ConnectError: [Errno 111] Connection refused\n","statusTrace":"  File \"/opt/hostedtoolcache/Python/3.10.18/x64/lib/python3.10/site-packages/allure_commons/_allure.py\", line 202, in impl\n    return func(*a, **kw)\n  File \"/home/runner/work/autotest_api/autotest_api/clients/api_client.py\", line 38, in post\n    return self.client.post(url, json=json, data=data, files=files)\n  File \"/opt/hostedtoolcache/Python/3.10.18/x64/lib/python3.10/site-packages/httpx/_client.py\", line 1144, in post\n    return self.request(\n  File \"/opt/hostedtoolcache/Python/3.10.18/x64/lib/python3.10/site-packages/httpx/_client.py\", line 825, in request\n    return self.send(request, auth=auth, follow_redirects=follow_redirects)\n  File \"/opt/hostedtoolcache/Python/3.10.18/x64/lib/python3.10/site-packages/httpx/_client.py\", line 914, in send\n    response = self._send_handling_auth(\n  File \"/opt/hostedtoolcache/Python/3.10.18/x64/lib/python3.10/site-packages/httpx/_client.py\", line 942, in _send_handling_auth\n    response = self._send_handling_redirects(\n  File \"/opt/hostedtoolcache/Python/3.10.18/x64/lib/python3.10/site-packages/httpx/_client.py\", line 979, in _send_handling_redirects\n    response = self._send_single_request(request)\n  File \"/opt/hostedtoolcache/Python/3.10.18/x64/lib/python3.10/site-packages/httpx/_client.py\", line 1014, in _send_single_request\n    response = transport.handle_request(request)\n  File \"/opt/hostedtoolcache/Python/3.10.18/x64/lib/python3.10/site-packages/httpx/_transports/default.py\", line 249, in handle_request\n    with map_httpcore_exceptions():\n  File \"/opt/hostedtoolcache/Python/3.10.18/x64/lib/python3.10/contextlib.py\", line 153, in __exit__\n    self.gen.throw(typ, value, traceback)\n  File \"/opt/hostedtoolcache/Python/3.10.18/x64/lib/python3.10/site-packages/httpx/_transports/default.py\", line 118, in map_httpcore_exceptions\n    raise mapped_exc(message) from exc\n","steps":[],"attachments":[{"uid":"dada60cef6321b8f","name":"cURL command","source":"dada60cef6321b8f.txt","type":"text/plain","size":409}],"parameters":[{"name":"url","value":"'/api/v1/users'"},{"name":"json","value":"{'email': 'coopertonya@example.com', 'password': '29CxfuCD_N', 'lastName': 'Silva', 'firstName': 'Jasmin', 'middleName': 'Ashley'}"},{"name":"data","value":"None"},{"name":"files","value":"None"}],"stepsCount":0,"shouldDisplayMessage":true,"attachmentsCount":1,"hasContent":true,"attachmentStep":false}],"attachments":[],"parameters":[{"name":"request","value":"CreateUserRequestSchema(email='coopertonya@example.com', password='29CxfuCD_N', last_name='Silva', first_name='Jasmin', middle_name='Ashley')"}],"stepsCount":1,"shouldDisplayMessage":false,"attachmentsCount":1,"hasContent":true,"attachmentStep":false}],"attachments":[],"parameters":[],"stepsCount":2,"shouldDisplayMessage":false,"attachmentsCount":1,"hasContent":true,"attachmentStep":false}],"testStage":{"status":"broken","statusMessage":"httpx.ConnectError: [Errno 111] Connection refused","statusTrace":"@contextlib.contextmanager\n    def map_httpcore_exceptions() -> typing.Iterator[None]:\n        global HTTPCORE_EXC_MAP\n        if len(HTTPCORE_EXC_MAP) == 0:\n            HTTPCORE_EXC_MAP = _load_httpcore_exceptions()\n        try:\n>           yield\n\n/opt/hostedtoolcache/Python/3.10.18/x64/lib/python3.10/site-packages/httpx/_transports/default.py:101: \n_ _ _ _ _ _ _ _ _ _ _ _ _ _ _ _ _ _ _ _ _ _ _ _ _ _ _ _ _ _ _ _ _ _ _ _ _ _ _ _ \n/opt/hostedtoolcache/Python/3.10.18/x64/lib/python3.10/site-packages/httpx/_transports/default.py:250: in handle_request\n    resp = self._pool.handle_request(req)\n/opt/hostedtoolcache/Python/3.10.18/x64/lib/python3.10/site-packages/httpcore/_sync/connection_pool.py:256: in handle_request\n    raise exc from None\n/opt/hostedtoolcache/Python/3.10.18/x64/lib/python3.10/site-packages/httpcore/_sync/connection_pool.py:236: in handle_request\n    response = connection.handle_request(\n/opt/hostedtoolcache/Python/3.10.18/x64/lib/python3.10/site-packages/httpcore/_sync/connection.py:101: in handle_request\n    raise exc\n/opt/hostedtoolcache/Python/3.10.18/x64/lib/python3.10/site-packages/httpcore/_sync/connection.py:78: in handle_request\n    stream = self._connect(request)\n/opt/hostedtoolcache/Python/3.10.18/x64/lib/python3.10/site-packages/httpcore/_sync/connection.py:124: in _connect\n    stream = self._network_backend.connect_tcp(**kwargs)\n/opt/hostedtoolcache/Python/3.10.18/x64/lib/python3.10/site-packages/httpcore/_backends/sync.py:207: in connect_tcp\n    with map_exceptions(exc_map):\n/opt/hostedtoolcache/Python/3.10.18/x64/lib/python3.10/contextlib.py:153: in __exit__\n    self.gen.throw(typ, value, traceback)\n_ _ _ _ _ _ _ _ _ _ _ _ _ _ _ _ _ _ _ _ _ _ _ _ _ _ _ _ _ _ _ _ _ _ _ _ _ _ _ _ \n\nmap = {<class 'TimeoutError'>: <class 'httpcore.ConnectTimeout'>, <class 'OSError'>: <class 'httpcore.ConnectError'>}\n\n    @contextlib.contextmanager\n    def map_exceptions(map: ExceptionMapping) -> typing.Iterator[None]:\n        try:\n            yield\n        except Exception as exc:  # noqa: PIE786\n            for from_exc, to_exc in map.items():\n                if isinstance(exc, from_exc):\n>                   raise to_exc(exc) from exc\nE                   httpcore.ConnectError: [Errno 111] Connection refused\n\n/opt/hostedtoolcache/Python/3.10.18/x64/lib/python3.10/site-packages/httpcore/_exceptions.py:14: ConnectError\n\nThe above exception was the direct cause of the following exception:\n\npublic_users_client = <clients.users.public_users_client.PublicUsersClient object at 0x7fe144c5d570>\n\n    @pytest.fixture\n    def function_user(public_users_client) -> UserFixture:\n        request = CreateUserRequestSchema()\n>       response = public_users_client.create_user(request)\n\nfixtures/users.py:34: \n_ _ _ _ _ _ _ _ _ _ _ _ _ _ _ _ _ _ _ _ _ _ _ _ _ _ _ _ _ _ _ _ _ _ _ _ _ _ _ _ \nclients/users/public_users_client.py:29: in create_user\n    response = self.create_user_api(request)\nclients/users/public_users_client.py:21: in create_user_api\n    return self.post(url=APIRoutes.USERS, json=request.model_dump(by_alias=True))\nclients/api_client.py:38: in post\n    return self.client.post(url, json=json, data=data, files=files)\n/opt/hostedtoolcache/Python/3.10.18/x64/lib/python3.10/site-packages/httpx/_client.py:1144: in post\n    return self.request(\n/opt/hostedtoolcache/Python/3.10.18/x64/lib/python3.10/site-packages/httpx/_client.py:825: in request\n    return self.send(request, auth=auth, follow_redirects=follow_redirects)\n/opt/hostedtoolcache/Python/3.10.18/x64/lib/python3.10/site-packages/httpx/_client.py:914: in send\n    response = self._send_handling_auth(\n/opt/hostedtoolcache/Python/3.10.18/x64/lib/python3.10/site-packages/httpx/_client.py:942: in _send_handling_auth\n    response = self._send_handling_redirects(\n/opt/hostedtoolcache/Python/3.10.18/x64/lib/python3.10/site-packages/httpx/_client.py:979: in _send_handling_redirects\n    response = self._send_single_request(request)\n/opt/hostedtoolcache/Python/3.10.18/x64/lib/python3.10/site-packages/httpx/_client.py:1014: in _send_single_request\n    response = transport.handle_request(request)\n/opt/hostedtoolcache/Python/3.10.18/x64/lib/python3.10/site-packages/httpx/_transports/default.py:249: in handle_request\n    with map_httpcore_exceptions():\n/opt/hostedtoolcache/Python/3.10.18/x64/lib/python3.10/contextlib.py:153: in __exit__\n    self.gen.throw(typ, value, traceback)\n_ _ _ _ _ _ _ _ _ _ _ _ _ _ _ _ _ _ _ _ _ _ _ _ _ _ _ _ _ _ _ _ _ _ _ _ _ _ _ _ \n\n    @contextlib.contextmanager\n    def map_httpcore_exceptions() -> typing.Iterator[None]:\n        global HTTPCORE_EXC_MAP\n        if len(HTTPCORE_EXC_MAP) == 0:\n            HTTPCORE_EXC_MAP = _load_httpcore_exceptions()\n        try:\n            yield\n        except Exception as exc:\n            mapped_exc = None\n    \n            for from_exc, to_exc in HTTPCORE_EXC_MAP.items():\n                if not isinstance(exc, from_exc):\n                    continue\n                # We want to map to the most specific exception we can find.\n                # Eg if `exc` is an `httpcore.ReadTimeout`, we want to map to\n                # `httpx.ReadTimeout`, not just `httpx.TimeoutException`.\n                if mapped_exc is None or issubclass(to_exc, mapped_exc):\n                    mapped_exc = to_exc\n    \n            if mapped_exc is None:  # pragma: no cover\n                raise\n    \n            message = str(exc)\n>           raise mapped_exc(message) from exc\nE           httpx.ConnectError: [Errno 111] Connection refused\n\n/opt/hostedtoolcache/Python/3.10.18/x64/lib/python3.10/site-packages/httpx/_transports/default.py:118: ConnectError","steps":[],"attachments":[{"uid":"46eb38c23e6214c5","name":"log","source":"46eb38c23e6214c5.txt","type":"text/plain","size":94}],"parameters":[],"stepsCount":0,"shouldDisplayMessage":true,"attachmentsCount":1,"hasContent":true,"attachmentStep":false},"afterStages":[{"name":"save_allure_environment_file::0","time":{"start":1761074886848,"stop":1761074886848,"duration":0},"status":"passed","steps":[],"attachments":[],"parameters":[],"stepsCount":0,"shouldDisplayMessage":false,"attachmentsCount":0,"hasContent":false,"attachmentStep":false}],"labels":[{"name":"severity","value":"normal"},{"name":"epic","value":"LMS service"},{"name":"tag","value":"REGRESSION"},{"name":"story","value":"Validate entity"},{"name":"subSuite","value":"Validate entity"},{"name":"suite","value":"Files"},{"name":"tag","value":"FILES"},{"name":"feature","value":"Files"},{"name":"parentSuite","value":"LMS service"},{"name":"tag","value":"VALIDATE_ENTITY"},{"name":"tag","value":"regression"},{"name":"tag","value":"files"},{"name":"host","value":"runnervmwhb2z"},{"name":"thread","value":"2453-MainThread"},{"name":"framework","value":"pytest"},{"name":"language","value":"cpython3"},{"name":"package","value":"tests.files.test_files"},{"name":"resultFormat","value":"allure2"}],"parameters":[],"links":[],"hidden":false,"retry":false,"extra":{"severity":"normal","retries":[],"categories":[{"name":"Test defects","matchedStatuses":[],"flaky":false}],"tags":["REGRESSION","VALIDATE_ENTITY","regression","files","FILES"]},"source":"bc9fa82fde0b0f3f.json","parameterValues":[]}